Workbook

Sheet Paper
J1: Resultados promedio paper
J2: Total | L2: Pacientes | N2: Sanos
B3: Escenario | C3: Descripción | D3: Inicio fuego | E3: Ubicación agentes | F3: Consideraciones | G3: Pacientes | H3: Sanos | I3: Total | J3: Vivos | K3: Muertos | L3: Vivos | M3: Muertos | N3: Vivos | O3: Muertos | P3: Tiempo evacuación
B4: 1 | C4: NO CHANGES ARE MADE TO THE BUILDING | D4: Random | E4: Random | F4: Fuego lado izquierdo | G4: =SUM(L4:M4) -> 40 | H4: =SUM(N4:O4) -> 59.333333 | I4: =G4+H4 -> 99.333333 | J4: =Resultados_paper!L3 -> 79 | K4: =Resultados_paper!M3 -> 21 | L4: =Resultados_paper!N3 -> 29 | M4: =Resultados_paper!O3 -> 11 | N4: =Resultados_paper!P3 -> 49 | O4: =Resultados_paper!Q3 -> 10.333333 | P4: =Resultados_paper!R3 -> 352
B5: 2 | C5: THE IMPACTOF THE LARGE NUMBER OF AGENTS TO EVACUATE | D5: Random | E5: Random | F5: Mayor ocupación | G5: =SUM(L5:M5) -> 108 | H5: =SUM(N5:O5) -> 182 | I5: =G5+H5 -> 290 | J5: =Resultados_paper!L4 -> 234 | K5: =Resultados_paper!M4 -> 56 | L5: =Resultados_paper!N4 -> 68 | M5: =Resultados_paper!O4 -> 40 | N5: =Resultados_paper!P4 -> 166 | O5: =Resultados_paper!Q4 -> 16 | P5: =Resultados_paper!R4 -> 553
B6: 3 | C6: THE IMPACTOF FIRE POSITIONING | D6: Centro | E6: Random | F6: Fuego en centro | G6: =SUM(L6:M6) -> 60 | H6: =SUM(N6:O6) -> 50 | I6: =G6+H6 -> 110 | J6: =Resultados_paper!L5 -> 54 | K6: =Resultados_paper!M5 -> 56 | L6: =Resultados_paper!N5 -> 27 | M6: =Resultados_paper!O5 -> 33 | N6: =Resultados_paper!P5 -> 27 | O6: =Resultados_paper!Q5 -> 23 | P6: =Resultados_paper!R5 -> 433
B7: 4 | C7: ADDING TWO ADDITIONAL TRANSVERSE DOORS TO THE EXISTING ONES | D7: Random | E7: Random | F7: Dos salidas adicionales | G7: =SUM(L7:M7) -> 45 | H7: =SUM(N7:O7) -> 55 | I7: =G7+H7 -> 100 | J7: =Resultados_paper!L6 -> 87 | K7: =Resultados_paper!M6 -> 8 | L7: =Resultados_paper!N6 -> 42 | M7: =Resultados_paper!O6 -> 3 | N7: =Resultados_paper!P6 -> 45 | O7: =Resultados_paper!Q6 -> 10 | P7: =Resultados_paper!R6 -> 198
B8: 5 | C8: THE IMPACTOF PEOPLE MOVING ALONG THE WALLS | D8: Random | E8: Random | F8: Todos conocen edif | G8: =SUM(L8:M8) -> 29 | H8: =SUM(N8:O8) -> 70.333333 | I8: =G8+H8 -> 99.333333 | J8: =Resultados_paper!L7 -> 93 | K8: =Resultados_paper!M7 -> 6 | L8: =Resultados_paper!N7 -> 23 | M8: =Resultados_paper!O7 -> 6 | N8: =Resultados_paper!P7 -> 70 | O8: =Resultados_paper!Q7 -> 0.33333333 | P8: =Resultados_paper!R7 -> 225
B9: 6 | C9: ALL EVACUEE AGENTS ARE HEALTHY AND UNAWARE OF THE BUILDING’S CONFIGURATION | D9: Random | E9: Random | F9: Fuego lado izquierdo, todos sanos y desconocen edif | H9: =J9+K9 -> 100 | I9: =G9+H9 -> 100 | J9: =Resultados_paper!L8 -> 78.666667 | K9: =Resultados_paper!M8 -> 21.333333 | P9: =Resultados_paper!R8 -> 320.8
B10: 7 | C10: ONLY50% OF AGENTS (REGARDLESS OF THEIR HEALTH STATUS) ARE FAMILIAR WITH THE BUILDING’S CONFIGURATION | D10: Random | E10: Random | F10: Solo 50% agentes conoce edif, no considera estado salud | G10: =SUM(L10:M10) -> 60 | H10: =SUM(N10:O10) -> 60 | I10: =G10+H10 -> 120 | J10: =Resultados_paper!L9 -> 89 | K10: =Resultados_paper!M9 -> 31 | L10: =Resultados_paper!N9 -> 47.333333 | M10: =Resultados_paper!O9 -> 12.666667 | N10: =Resultados_paper!P9 -> 41.666667 | O10: =Resultados_paper!Q9 -> 18.333333 | P10: =Resultados_paper!R9 -> 293.6
B11: 8 | C11: ONLY50% OF AGENTS (CONSIDERATION OF THEIR HEALTH STATUS) ARE FAMILIAR WITH THE BUILDING’S CONFIGURATION | D11: Random | E11: Random | F11: 50% agentes conoce edif, considerar estado salud | G11: =SUM(L11:M11) -> 58.333333 | H11: =SUM(N11:O11) -> 54.666667 | I11: =G11+H11 -> 113 | J11: =Resultados_paper!L10 -> 101.33333 | K11: =Resultados_paper!M10 -> 11.666667 | L11: =Resultados_paper!N10 -> 50.666667 | M11: =Resultados_paper!O10 -> 7.6666667 | N11: =Resultados_paper!P10 -> 50.666667 | O11: =Resultados_paper!Q10 -> 4 | P11: =Resultados_paper!R10 -> 366.66667
B12: 9 | C12: THE IMPACTOF ADDING EMERGENCY EXITS TO THE HOSPITAL BUILDING | D12: Random | E12: Random | F12: Adicionar 2 salidas y 5 puertas de emergencia | G12: =SUM(L12:M12) -> 50 | H12: =SUM(N12:O12) -> 50 | I12: =G12+H12 -> 100 | J12: =Resultados_paper!L11 -> 99 | K12: =Resultados_paper!M11 -> 1 | L12: =Resultados_paper!N11 -> 49.333333 | M12: =Resultados_paper!O11 -> 0.66666667 | N12: =Resultados_paper!P11 -> 49.666667 | O12: =Resultados_paper!Q11 -> 0.33333333 | P12: =Resultados_paper!R11 -> 346.66667

Sheet Resultados_paper
A1: Table paper | K1: Resultados promedio compilados
A2: Table 3 | B2: Escenario No. 1: NO CHANGES ARE MADE TO THE BUILDING | K2: {=TRANSPOSE(B4:B11)} -> Individuos en el ambiente | L2: Número de individuos vivos | M2: Número de individuos muertos | N2: Número de pacientes vivos | O2: Número de pacientes muertos | P2: Número de sanos vivos | Q2: Número de sanos muertos | R2: Tiempo promedio de evacuación
B3: Resultados | C3: S1 | D3: S2 | E3: S3 | F3: Promedio | G3: Desv. Estandar | J3: Escenario No. 1 | K3: {=TRANSPOSE(F4:F11)} -> 100 | L3: 79 | M3: 21 | N3: 29 | O3: 11 | P3: 49 | Q3: 10.333333 | R3: 352
B4: Individuos en el ambiente | C4: 100 | D4: 100 | E4: 100 | F4: =AVERAGE(C4:E4) -> 100 | G4: =_xlfn.STDEV.P(C4:E4) -> 0 | J4: Escenario No. 2 | K4: {=TRANSPOSE(F15:F22)} -> 290 | L4: 234 | M4: 56 | N4: 68 | O4: 40 | P4: 166 | Q4: 16 | R4: 553
B5: Número de individuos vivos | C5: 75 | D5: 85 | E5: 77 | F5: =AVERAGE(C5:E5) -> 79 | G5: =_xlfn.STDEV.P(C5:E5) -> 4.3204938 | J5: Escenario No. 3 | K5: {=TRANSPOSE(F26:F33)} -> 110 | L5: 54 | M5: 56 | N5: 27 | O5: 33 | P5: 27 | Q5: 23 | R5: 433
B6: Número de individuos muertos | C6: 25 | D6: 15 | E6: 23 | F6: =AVERAGE(C6:E6) -> 21 | G6: =_xlfn.STDEV.P(C6:E6) -> 4.3204938 | J6: Escenario No. 4 | K6: {=TRANSPOSE(F37:F44)} -> 100 | L6: 87 | M6: 8 | N6: 42 | O6: 3 | P6: 45 | Q6: 10 | R6: 198
B7: Número de pacientes vivos | C7: 28 | D7: 32 | E7: 27 | F7: =AVERAGE(C7:E7) -> 29 | G7: =_xlfn.STDEV.P(C7:E7) -> 2.1602469 | J7: Escenario No. 5 | K7: {=TRANSPOSE(F48:F55)} -> 100 | L7: 93 | M7: 6 | N7: 23 | O7: 6 | P7: 70 | Q7: 0.33333333 | R7: 225
B8: Número de pacientes muertos | C8: 12 | D8: 8 | E8: 13 | F8: =AVERAGE(C8:E8) -> 11 | G8: =_xlfn.STDEV.P(C8:E8) -> 2.1602469 | J8: Escenario No. 6 | K8: {=TRANSPOSE(F59:F66)} -> 100 | L8: 78.666667 | M8: 21.333333 | N8: 0 | O8: 0 | P8: 0 | Q8: 0 | R8: 320.8
B9: Número de sanos vivos | C9: 45 | D9: 52 | E9: 50 | F9: =AVERAGE(C9:E9) -> 49 | G9: =_xlfn.STDEV.P(C9:E9) -> 2.9439203 | J9: Escenario No. 7 | K9: {=TRANSPOSE(F70:F77)} -> 120 | L9: 89 | M9: 31 | N9: 47.333333 | O9: 12.666667 | P9: 41.666667 | Q9: 18.333333 | R9: 293.6
B10: Número de sanos muertos | C10: 13 | D10: 8 | E10: 10 | F10: =AVERAGE(C10:E10) -> 10.333333 | G10: =_xlfn.STDEV.P(C10:E10) -> 2.0548047 | J10: Escenario No. 8 | K10: {=TRANSPOSE(F98:F105)} -> 113 | L10: 101.33333 | M10: 11.666667 | N10: 50.666667 | O10: 7.6666667 | P10: 50.666667 | Q10: 4 | R10: 366.66667
B11: Tiempo promedio de evacuación | C11: 352 | D11: 345 | E11: 359 | F11: =AVERAGE(C11:E11) -> 352 | G11: =_xlfn.STDEV.P(C11:E11) -> 5.7154761 | J11: Escenario No. 9 | K11: {=TRANSPOSE(F109:F116)} -> 100 | L11: 99 | M11: 1 | N11: 49.333333 | O11: 0.66666667 | P11: 49.666667 | Q11: 0.33333333 | R11: 346.66667
A13: Table 4 | B13: Escenario No. 2: THE IMPACTOF THE LARGE NUMBER OF AGENTS TO EVACUATE
B14: Resultados | C14: S1 | D14: S2 | E14: S3 | F14: Promedio | G14: Desv. Estandar
B15: Individuos en el ambiente | C15: 290 | D15: 290 | E15: 290 | F15: =AVERAGE(C15:E15) -> 290 | G15: =_xlfn.STDEV.P(C15:E15) -> 0
B16: Número de individuos vivos | C16: 230 | D16: 235 | E16: 237 | F16: =AVERAGE(C16:E16) -> 234 | G16: =_xlfn.STDEV.P(C16:E16) -> 2.9439203
B17: Número de individuos muertos | C17: 58 | D17: 57 | E17: 53 | F17: =AVERAGE(C17:E17) -> 56 | G17: =_xlfn.STDEV.P(C17:E17) -> 2.1602469
B18: Número de pacientes vivos | C18: 65 | D18: 70 | E18: 69 | F18: =AVERAGE(C18:E18) -> 68 | G18: =_xlfn.STDEV.P(C18:E18) -> 2.1602469
B19: Número de pacientes muertos | C19: 42 | D19: 37 | E19: 41 | F19: =AVERAGE(C19:E19) -> 40 | G19: =_xlfn.STDEV.P(C19:E19) -> 2.1602469
B20: Número de sanos vivos | C20: 160 | D20: 168 | E20: 170 | F20: =AVERAGE(C20:E20) -> 166 | G20: =_xlfn.STDEV.P(C20:E20) -> 4.3204938
B21: Número de sanos muertos | C21: 19 | D21: 14 | E21: 15 | F21: =AVERAGE(C21:E21) -> 16 | G21: =_xlfn.STDEV.P(C21:E21) -> 2.1602469
B22: Tiempo promedio de evacuación | C22: 555 | D22: 570 | E22: 534 | F22: =AVERAGE(C22:E22) -> 553 | G22: =_xlfn.STDEV.P(C22:E22) -> 14.764823
A24: Table 5 | B24: Escenario No. 3: THE IMPACTOF FIRE POSITIONING
B25: Resultados | C25: S1 | D25: S2 | E25: S3 | F25: Promedio | G25: Desv. Estandar
B26: Individuos en el ambiente | C26: 110 | D26: 110 | E26: 110 | F26: =AVERAGE(C26:E26) -> 110 | G26: =_xlfn.STDEV.P(C26:E26) -> 0
B27: Número de individuos vivos | C27: 57 | D27: 50 | E27: 55 | F27: =AVERAGE(C27:E27) -> 54 | G27: =_xlfn.STDEV.P(C27:E27) -> 2.9439203
B28: Número de individuos muertos | C28: 57 | D28: 58 | E28: 53 | F28: =AVERAGE(C28:E28) -> 56 | G28: =_xlfn.STDEV.P(C28:E28) -> 2.1602469
B29: Número de pacientes vivos | C29: 23 | D29: 30 | E29: 28 | F29: =AVERAGE(C29:E29) -> 27 | G29: =_xlfn.STDEV.P(C29:E29) -> 2.9439203
B30: Número de pacientes muertos | C30: 30 | D30: 35 | E30: 34 | F30: =AVERAGE(C30:E30) -> 33 | G30: =_xlfn.STDEV.P(C30:E30) -> 2.1602469
B31: Número de sanos vivos | C31: 28 | D31: 25 | E31: 28 | F31: =AVERAGE(C31:E31) -> 27 | G31: =_xlfn.STDEV.P(C31:E31) -> 1.4142136
B32: Número de sanos muertos | C32: 22 | D32: 25 | E32: 22 | F32: =AVERAGE(C32:E32) -> 23 | G32: =_xlfn.STDEV.P(C32:E32) -> 1.4142136
B33: Tiempo promedio de evacuación | C33: 436 | D33: 435 | E33: 428 | F33: =AVERAGE(C33:E33) -> 433 | G33: =_xlfn.STDEV.P(C33:E33) -> 3.5590261
A35: Table 6 | B35: Escenario No. 4: ADDING TWO ADDITIONAL TRANSVERSE DOORS TO THE EXISTING ONES
B36: Resultados | C36: S1 | D36: S2 | E36: S3 | F36: Promedio | G36: Desv. Estandar
B37: Individuos en el ambiente | C37: 100 | D37: 100 | E37: 100 | F37: =AVERAGE(C37:E37) -> 100 | G37: =_xlfn.STDEV.P(C37:E37) -> 0
B38: Número de individuos vivos | C38: 88 | D38: 90 | E38: 83 | F38: =AVERAGE(C38:E38) -> 87 | G38: =_xlfn.STDEV.P(C38:E38) -> 2.9439203
B39: Número de individuos muertos | C39: 9 | D39: 1 | E39: 14 | F39: =AVERAGE(C39:E39) -> 8 | G39: =_xlfn.STDEV.P(C39:E39) -> 5.3541261
B40: Número de pacientes vivos | C40: 43 | D40: 44 | E40: 39 | F40: =AVERAGE(C40:E40) -> 42 | G40: =_xlfn.STDEV.P(C40:E40) -> 2.1602469
B41: Número de pacientes muertos | C41: 2 | D41: 4 | E41: 3 | F41: =AVERAGE(C41:E41) -> 3 | G41: =_xlfn.STDEV.P(C41:E41) -> 0.81649658
B42: Número de sanos vivos | C42: 47 | D42: 42 | E42: 46 | F42: =AVERAGE(C42:E42) -> 45 | G42: =_xlfn.STDEV.P(C42:E42) -> 2.1602469
B43: Número de sanos muertos | C43: 8 | D43: 13 | E43: 9 | F43: =AVERAGE(C43:E43) -> 10 | G43: =_xlfn.STDEV.P(C43:E43) -> 2.1602469
...

Sheet Net_logo
K1: Resultados promedio Net Logo
K2: Total | M2: Pacientes | O2: Sanos
B3: Escenario | C3: Descripción | D3: Inicio fuego | E3: Ubicación agentes | F3: Consideraciones | G3: Prob_fuego | H3: Pacientes | I3: Sanos | J3: Total | K3: Vivos | L3: Muertos | M3: Vivos | N3: Muertos | O3: Vivos | P3: Muertos | Q3: Tiempo evacuación
B4: 1 | C4: NO CHANGES ARE MADE TO THE BUILDING | D4: Random | E4: Random | F4: Fuego laterales | G4: 95 | H4: =SUM(M4:N4) -> 40 | I4: =SUM(O4:P4) -> 60 | J4: =H4+I4 -> 100 | K4: =Resultados_net_logo!N3 -> 89.8 | L4: =Resultados_net_logo!O3 -> 10.2 | M4: =Resultados_net_logo!P3 -> 35.8 | N4: =Resultados_net_logo!Q3 -> 4.2 | O4: =Resultados_net_logo!R3 -> 54 | P4: =Resultados_net_logo!S3 -> 6 | Q4: =Resultados_net_logo!T3 -> 50.6
B5: 2 | C5: THE IMPACTOF THE LARGE NUMBER OF AGENTS TO EVACUATE | D5: Random | E5: Random | F5: Mayor ocupación | G5: 95 | H5: =SUM(M5:N5) -> 108 | I5: =SUM(O5:P5) -> 182 | J5: =H5+I5 -> 290 | K5: =Resultados_net_logo!N4 -> 221.4 | L5: =Resultados_net_logo!O4 -> 68.6 | M5: =Resultados_net_logo!P4 -> 79.2 | N5: =Resultados_net_logo!Q4 -> 28.8 | O5: =Resultados_net_logo!R4 -> 142.2 | P5: =Resultados_net_logo!S4 -> 39.8 | Q5: =Resultados_net_logo!T4 -> 71.6
B6: 3 | C6: THE IMPACTOF FIRE POSITIONING | D6: Centro | E6: Random | F6: Fuego en centro | G6: 95 | H6: =SUM(M6:N6) -> 60 | I6: =SUM(O6:P6) -> 50 | J6: =H6+I6 -> 110 | K6: =Resultados_net_logo!N5 -> 81.2 | L6: =Resultados_net_logo!O5 -> 28.8 | M6: =Resultados_net_logo!P5 -> 40.2 | N6: =Resultados_net_logo!Q5 -> 19.8 | O6: =Resultados_net_logo!R5 -> 41 | P6: =Resultados_net_logo!S5 -> 9 | Q6: =Resultados_net_logo!T5 -> 36
B7: 4 | C7: ADDING TWO ADDITIONAL TRANSVERSE DOORS TO THE EXISTING ONES | D7: Random | E7: Random | F7: Dos salidas adicionales | G7: 95 | H7: =SUM(M7:N7) -> 45 | I7: =SUM(O7:P7) -> 55 | J7: =H7+I7 -> 100 | K7: =Resultados_net_logo!N6 -> 93.8 | L7: =Resultados_net_logo!O6 -> 6.2 | M7: =Resultados_net_logo!P6 -> 40.4 | N7: =Resultados_net_logo!Q6 -> 4.6 | O7: =Resultados_net_logo!R6 -> 53.4 | P7: =Resultados_net_logo!S6 -> 1.6 | Q7: =Resultados_net_logo!T6 -> 41.2
B8: 5 | C8: THE IMPACTOF PEOPLE MOVING ALONG THE WALLS | D8: Random | E8: Random | F8: Todos conocen edif | G8: 95 | H8: =SUM(M8:N8) -> 40 | I8: =SUM(O8:P8) -> 60 | J8: =H8+I8 -> 100 | K8: =Resultados_net_logo!N7 -> 91.4 | L8: =Resultados_net_logo!O7 -> 8.6 | M8: =Resultados_net_logo!P7 -> 35.4 | N8: =Resultados_net_logo!Q7 -> 4.6 | O8: =Resultados_net_logo!R7 -> 56 | P8: =Resultados_net_logo!S7 -> 4 | Q8: =Resultados_net_logo!T7 -> 28.6
B9: 6 | C9: ALL EVACUEE AGENTS ARE HEALTHY AND UNAWARE OF THE BUILDING’S CONFIGURATION | D9: Random | E9: Random | F9: Fuego laterales, todos sanos y desconocen edif | G9: 95 | I9: =K9+L9 -> 100 | J9: =H9+I9 -> 100 | K9: =Resultados_net_logo!N8 -> 86.4 | L9: =Resultados_net_logo!O8 -> 13.6 | Q9: =Resultados_net_logo!T8 -> 48.6
B10: 7 | C10: ONLY50% OF AGENTS (REGARDLESS OF THEIR HEALTH STATUS) ARE FAMILIAR WITH THE BUILDING’S CONFIGURATION | D10: Random | E10: Random | F10: Solo 50% agentes conoce edif, no considera estado salud | G10: 95 | H10: =SUM(M10:N10) -> 60.8 | I10: =SUM(O10:P10) -> 59.2 | J10: =H10+I10 -> 120 | K10: =Resultados_net_logo!N9 -> 101 | L10: =Resultados_net_logo!O9 -> 19 | M10: =Resultados_net_logo!P9 -> 55.6 | N10: =Resultados_net_logo!Q9 -> 5.2 | O10: =Resultados_net_logo!R9 -> 45.4 | P10: =Resultados_net_logo!S9 -> 13.8 | Q10: =Resultados_net_logo!T9 -> 48.8
B11: 8 | C11: ONLY50% OF AGENTS (CONSIDERATION OF THEIR HEALTH STATUS) ARE FAMILIAR WITH THE BUILDING’S CONFIGURATION | D11: Random | E11: Random | F11: 50% agentes conoce edif, considerar estado salud | G11: 95 | H11: =SUM(M11:N11) -> 58 | I11: =SUM(O11:P11) -> 55 | J11: =H11+I11 -> 113 | K11: =Resultados_net_logo!N10 -> 97.8 | L11: =Resultados_net_logo!O10 -> 15.2 | M11: =Resultados_net_logo!P10 -> 47.2 | N11: =Resultados_net_logo!Q10 -> 10.8 | O11: =Resultados_net_logo!R10 -> 50.6 | P11: =Resultados_net_logo!S10 -> 4.4 | Q11: =Resultados_net_logo!T10 -> 54
B12: 9 | C12: THE IMPACTOF ADDING EMERGENCY EXITS TO THE HOSPITAL BUILDING | D12: Random | E12: Random | F12: Adicionar 2 salidas y 5 puertas de emergencia | G12: 95 | H12: =SUM(M12:N12) -> 50 | I12: =SUM(O12:P12) -> 50 | J12: =H12+I12 -> 100 | K12: =Resultados_net_logo!N11 -> 97.2 | L12: =Resultados_net_logo!O11 -> 2.8 | M12: =Resultados_net_logo!P11 -> 47.8 | N12: =Resultados_net_logo!Q11 -> 2.2 | O12: =Resultados_net_logo!R11 -> 49.4 | P12: =Resultados_net_logo!S11 -> 0.6 | Q12: =Resultados_net_logo!T11 -> 35.2

Sheet Resultados_net_logo
A1: Table paper | M1: Resultados promedio compilados
A2: Table 3 | B2: Escenario No. 1: NO CHANGES ARE MADE TO THE BUILDING | M2: {=TRANSPOSE(B4:B11)} -> Individuos en el ambiente | N2: Número de individuos vivos | O2: Número de individuos muertos | P2: Número de pacientes vivos | Q2: Número de pacientes muertos | R2: Número de sanos vivos | S2: Número de sanos muertos | T2: Tiempo promedio de evacuación
B3: Resultados | C3: S1 | D3: S2 | E3: S3 | F3: S4 | G3: S5 | H3: Promedio | J3: DE | L3: Escenario No. 1 | M3: {=TRANSPOSE(H4:H11)} -> 100 | N3: 89.8 | O3: 10.2 | P3: 35.8 | Q3: 4.2 | R3: 54 | S3: 6 | T3: 50.6
B4: Individuos en el ambiente | C4: =C5+C6 -> 100 | D4: =D5+D6 -> 100 | E4: =E5+E6 -> 100 | F4: =F5+F6 -> 100 | G4: =G5+G6 -> 100 | H4: =AVERAGE(C4:G4) -> 100 | I4: ± | J4: =_xlfn.STDEV.P(C4:G4) -> 0 | L4: Escenario No. 2 | M4: {=TRANSPOSE(H16:H23)} -> 290 | N4: 221.4 | O4: 68.6 | P4: 79.2 | Q4: 28.8 | R4: 142.2 | S4: 39.8 | T4: 71.6
B5: Número de individuos vivos | C5: 89 | D5: 81 | E5: 93 | F5: 89 | G5: 97 | H5: =AVERAGE(C5:G5) -> 89.8 | I5: ± | J5: =_xlfn.STDEV.P(C5:G5) -> 5.3065997 | L5: Escenario No. 3 | M5: {=TRANSPOSE(H28:H35)} -> 110 | N5: 81.2 | O5: 28.8 | P5: 40.2 | Q5: 19.8 | R5: 41 | S5: 9 | T5: 36
B6: Número de individuos muertos | C6: 11 | D6: 19 | E6: 7 | F6: 11 | G6: 3 | H6: =AVERAGE(C6:G6) -> 10.2 | I6: ± | J6: =_xlfn.STDEV.P(C6:G6) -> 5.3065997 | L6: Escenario No. 4 | M6: {=TRANSPOSE(H40:H47)} -> 100 | N6: 93.8 | O6: 6.2 | P6: 40.4 | Q6: 4.6 | R6: 53.4 | S6: 1.6 | T6: 41.2
B7: Número de pacientes vivos | C7: 36 | D7: 31 | E7: 35 | F7: 37 | G7: 40 | H7: =AVERAGE(C7:G7) -> 35.8 | I7: ± | J7: =_xlfn.STDEV.P(C7:G7) -> 2.9257478 | L7: Escenario No. 5 | M7: {=TRANSPOSE(H52:H59)} -> 100 | N7: 91.4 | O7: 8.6 | P7: 35.4 | Q7: 4.6 | R7: 56 | S7: 4 | T7: 28.6
B8: Número de pacientes muertos | C8: 4 | D8: 9 | E8: 5 | F8: 3 | G8: 0 | H8: =AVERAGE(C8:G8) -> 4.2 | I8: ± | J8: =_xlfn.STDEV.P(C8:G8) -> 2.9257478 | L8: Escenario No. 6 | M8: {=TRANSPOSE(H64:H71)} -> 100 | N8: 86.4 | O8: 13.6 | P8: 0 | Q8: 0 | R8: 86.4 | S8: 13.6 | T8: 48.6
B9: Número de sanos vivos | C9: 53 | D9: 50 | E9: 58 | F9: 52 | G9: 57 | H9: =AVERAGE(C9:G9) -> 54 | I9: ± | J9: =_xlfn.STDEV.P(C9:G9) -> 3.0331502 | L9: Escenario No. 7 | M9: {=TRANSPOSE(H76:H83)} -> 120 | N9: 101 | O9: 19 | P9: 55.6 | Q9: 5.2 | R9: 45.4 | S9: 13.8 | T9: 48.8
B10: Número de sanos muertos | C10: 7 | D10: 10 | E10: 2 | F10: 8 | G10: 3 | H10: =AVERAGE(C10:G10) -> 6 | I10: ± | J10: =_xlfn.STDEV.P(C10:G10) -> 3.0331502 | L10: Escenario No. 8 | M10: {=TRANSPOSE(H106:H113)} -> 113 | N10: 97.8 | O10: 15.2 | P10: 47.2 | Q10: 10.8 | R10: 50.6 | S10: 4.4 | T10: 54
B11: Tiempo promedio de evacuación | C11: 50 | D11: 48 | E11: 52 | F11: 54 | G11: 49 | H11: =AVERAGE(C11:G11) -> 50.6 | I11: ± | J11: =_xlfn.STDEV.P(C11:G11) -> 2.1540659 | L11: Escenario No. 9 | M11: {=TRANSPOSE(H118:H125)} -> 100 | N11: 97.2 | O11: 2.8 | P11: 47.8 | Q11: 2.2 | R11: 49.4 | S11: 0.6 | T11: 35.2
B12: Si : Simulación i, donde i = 1…5; DE: Desviación estándar.
A14: Table 4 | B14: Escenario No. 2: THE IMPACTOF THE LARGE NUMBER OF AGENTS TO EVACUATE
B15: Resultados | C15: S1 | D15: S2 | E15: S3 | F15: S4 | G15: S5 | H15: Promedio | J15: DE | L15: Escenario | M15: Agentes vivos | N15: Agentes muertos
B16: Individuos en el ambiente | C16: =C17+C18 -> 290 | D16: =D17+D18 -> 290 | E16: =E17+E18 -> 290 | F16: =F17+F18 -> 290 | G16: =G17+G18 -> 290 | H16: =AVERAGE(C16:G16) -> 290 | I16: ± | J16: =_xlfn.STDEV.P(C16:G16) -> 0 | L16: 1 | M16: =N3 -> 89.8 | N16: =O3 -> 10.2
B17: Número de individuos vivos | C17: 233 | D17: 246 | E17: 199 | F17: 232 | G17: 197 | H17: =AVERAGE(C17:G17) -> 221.4 | I17: ± | J17: =_xlfn.STDEV.P(C17:G17) -> 19.744366 | L17: 2 | M17: =N4 -> 221.4 | N17: =O4 -> 68.6
B18: Número de individuos muertos | C18: 57 | D18: 44 | E18: 91 | F18: 58 | G18: 93 | H18: =AVERAGE(C18:G18) -> 68.6 | I18: ± | J18: =_xlfn.STDEV.P(C18:G18) -> 19.744366 | L18: 3 | M18: =N5 -> 81.2 | N18: =O5 -> 28.8
B19: Número de pacientes vivos | C19: 84 | D19: 92 | E19: 65 | F19: 84 | G19: 71 | H19: =AVERAGE(C19:G19) -> 79.2 | I19: ± | J19: =_xlfn.STDEV.P(C19:G19) -> 9.7857039 | L19: 4 | M19: =N6 -> 93.8 | N19: =O6 -> 6.2
B20: Número de pacientes muertos | C20: 24 | D20: 16 | E20: 43 | F20: 24 | G20: 37 | H20: =AVERAGE(C20:G20) -> 28.8 | I20: ± | J20: =_xlfn.STDEV.P(C20:G20) -> 9.7857039 | L20: 5 | M20: =N7 -> 91.4 | N20: =O7 -> 8.6
B21: Número de sanos vivos | C21: 149 | D21: 154 | E21: 134 | F21: 148 | G21: 126 | H21: =AVERAGE(C21:G21) -> 142.2 | I21: ± | J21: =_xlfn.STDEV.P(C21:G21) -> 10.476641 | L21: 6 | M21: =N8 -> 86.4 | N21: =O8 -> 13.6
B22: Número de sanos muertos | C22: 33 | D22: 28 | E22: 48 | F22: 34 | G22: 56 | H22: =AVERAGE(C22:G22) -> 39.8 | I22: ± | J22: =_xlfn.STDEV.P(C22:G22) -> 10.476641 | L22: 7 | M22: =N9 -> 101 | N22: =O9 -> 19
B23: Tiempo promedio de evacuación | C23: 77 | D23: 73 | E23: 65 | F23: 81 | G23: 62 | H23: =AVERAGE(C23:G23) -> 71.6 | I23: ± | J23: =_xlfn.STDEV.P(C23:G23) -> 7.1442284 | L23: 8 | M23: =N10 -> 97.8 | N23: =O10 -> 15.2
B24: Si : Simulación i, donde i = 1…5; DE: Desviación estándar. | L24: 9 | M24: =N11 -> 97.2 | N24: =O11 -> 2.8
A26: Table 5 | B26: Escenario No. 3: THE IMPACTOF FIRE POSITIONING
B27: Resultados | C27: S1 | D27: S2 | E27: S3 | F27: S4 | G27: S5 | H27: Promedio | J27: DE | L27: Escenario | M27: Agentes en el ambiente | N27: Tiempo promedio de evacuación
B28: Individuos en el ambiente | C28: =C29+C30 -> 110 | D28: =D29+D30 -> 110 | E28: =E29+E30 -> 110 | F28: =F29+F30 -> 110 | G28: =G29+G30 -> 110 | H28: =AVERAGE(C28:G28) -> 110 | I28: ± | J28: =_xlfn.STDEV.P(C28:G28) -> 0 | L28: 1 | M28: =M3 -> 100 | N28: =T3 -> 50.6
B29: Número de individuos vivos | C29: 83 | D29: 89 | E29: 72 | F29: 80 | G29: 82 | H29: =AVERAGE(C29:G29) -> 81.2 | I29: ± | J29: =_xlfn.STDEV.P(C29:G29) -> 5.4918121 | L29: 2 | M29: =M4 -> 290 | N29: =T4 -> 71.6
B30: Número de individuos muertos | C30: 27 | D30: 21 | E30: 38 | F30: 30 | G30: 28 | H30: =AVERAGE(C30:G30) -> 28.8 | I30: ± | J30: =_xlfn.STDEV.P(C30:G30) -> 5.4918121 | L30: 3 | M30: =M5 -> 110 | N30: =T5 -> 36
B31: Número de pacientes vivos | C31: 42 | D31: 47 | E31: 33 | F31: 41 | G31: 38 | H31: =AVERAGE(C31:G31) -> 40.2 | I31: ± | J31: =_xlfn.STDEV.P(C31:G31) -> 4.621688 | L31: 4 | M31: =M6 -> 100 | N31: =T6 -> 41.2
B32: Número de pacientes muertos | C32: 18 | D32: 13 | E32: 27 | F32: 19 | G32: 22 | H32: =AVERAGE(C32:G32) -> 19.8 | I32: ± | J32: =_xlfn.STDEV.P(C32:G32) -> 4.621688 | L32: 5 | M32: =M7 -> 100 | N32: =T7 -> 28.6
B33: Número de sanos vivos | C33: 41 | D33: 42 | E33: 39 | F33: 39 | G33: 44 | H33: =AVERAGE(C33:G33) -> 41 | I33: ± | J33: =_xlfn.STDEV.P(C33:G33) -> 1.8973666 | L33: 6 | M33: =M8 -> 100 | N33: =T8 -> 48.6
B34: Número de sanos muertos | C34: 9 | D34: 8 | E34: 11 | F34: 11 | G34: 6 | H34: =AVERAGE(C34:G34) -> 9 | I34: ± | J34: =_xlfn.STDEV.P(C34:G34) -> 1.8973666 | L34: 7 | M34: =M9 -> 120 | N34: =T9 -> 48.8
B35: Tiempo promedio de evacuación | C35: 24 | D35: 44 | E35: 32 | F35: 40 | G35: 40 | H35: =AVERAGE(C35:G35) -> 36 | I35: ± | J35: =_xlfn.STDEV.P(C35:G35) -> 7.1554175 | L35: 8 | M35: =M10 -> 113 | N35: =T10 -> 54
B36: Si : Simulación i, donde i = 1…5; DE: Desviación estándar. | L36: 9 | M36: =M11 -> 100 | N36: =T11 -> 35.2
A38: Table 6 | B38: Escenario No. 4: ADDING TWO ADDITIONAL TRANSVERSE DOORS TO THE EXISTING ONES
B39: Resultados | C39: S1 | D39: S2 | E39: S3 | F39: S4 | G39: S5 | H39: Promedio | J39: DE | L39: Escenario | M39: Pacientes vivos | N39: Pacientes muertos | O39: Sanos vivos | P39: Sanos muertos
B40: Individuos en el ambiente | C40: =C41+C42 -> 100 | D40: =D41+D42 -> 100 | E40: =E41+E42 -> 100 | F40: =F41+F42 -> 100 | G40: =G41+G42 -> 100 | H40: =AVERAGE(C40:G40) -> 100 | I40: ± | J40: =_xlfn.STDEV.P(C40:G40) -> 0 | L40: 1 | M40: =P3 -> 35.8 | N40: =Q3 -> 4.2 | O40: =R3 -> 54 | P40: =S3 -> 6
B41: Número de individuos vivos | C41: 96 | D41: 94 | E41: 91 | F41: 94 | G41: 94 | H41: =AVERAGE(C41:G41) -> 93.8 | I41: ± | J41: =_xlfn.STDEV.P(C41:G41) -> 1.6 | L41: 2 | M41: =P4 -> 79.2 | N41: =Q4 -> 28.8 | O41: =R4 -> 142.2 | P41: =S4 -> 39.8
B42: Número de individuos muertos | C42: 4 | D42: 6 | E42: 9 | F42: 6 | G42: 6 | H42: =AVERAGE(C42:G42) -> 6.2 | I42: ± | J42: =_xlfn.STDEV.P(C42:G42) -> 1.6 | L42: 3 | M42: =P5 -> 40.2 | N42: =Q5 -> 19.8 | O42: =R5 -> 41 | P42: =S5 -> 9
B43: Número de pacientes vivos | C43: 43 | D43: 40 | E43: 38 | F43: 42 | G43: 39 | H43: =AVERAGE(C43:G43) -> 40.4 | I43: ± | J43: =_xlfn.STDEV.P(C43:G43) -> 1.8547237 | L43: 4 | M43: =P6 -> 40.4 | N43: =Q6 -> 4.6 | O43: =R6 -> 53.4 | P43: =S6 -> 1.6
...

Sheet Resultados_net_logo(no_vel)
M1: Resultados promedio compilados
A2: Table 3 | B2: Escenario No. 1: NO CHANGES ARE MADE TO THE BUILDING | M2: {=TRANSPOSE(B4:B11)} -> Individuos en el ambiente | N2: Número de individuos vivos | O2: Número de individuos muertos | P2: Número de pacientes vivos | Q2: Número de pacientes muertos | R2: Número de sanos vivos | S2: Número de sanos muertos | T2: Tiempo promedio de evacuación
B3: Resultados | C3: S1 | D3: S2 | E3: S3 | F3: S4 | G3: S5 | H3: Promedio | I3: Desv. Estandar | L3: Escenario No. 1 | M3: {=TRANSPOSE(H4:H11)} -> 100 | N3: 87.2 | O3: 12.8 | P3: 34.4 | Q3: 5.6 | R3: 52.8 | S3: 7.2 | T3: 56
B4: Individuos en el ambiente | C4: =C5+C6 -> 100 | D4: =D5+D6 -> 100 | E4: =E5+E6 -> 100 | F4: =F5+F6 -> 100 | G4: =G5+G6 -> 100 | H4: =AVERAGE(C4:G4) -> 100 | I4: =_xlfn.STDEV.P(C4:G4) -> 0 | L4: Escenario No. 2 | M4: {=TRANSPOSE(H15:H22)} -> 290 | N4: 197.6 | O4: 92.4 | P4: 71.4 | Q4: 36.6 | R4: 126.2 | S4: 55.8 | T4: 71.6
B5: Número de individuos vivos | C5: 82 | D5: 87 | E5: 98 | F5: 93 | G5: 76 | H5: =AVERAGE(C5:G5) -> 87.2 | I5: =_xlfn.STDEV.P(C5:G5) -> 7.7820306 | L5: Escenario No. 3 | M5: {=TRANSPOSE(H26:H33)} -> 110 | N5: 72.2 | O5: 37.8 | P5: 37.8 | Q5: 22.2 | R5: 34.4 | S5: 15.6 | T5: 45.2
B6: Número de individuos muertos | C6: 18 | D6: 13 | E6: 2 | F6: 7 | G6: 24 | H6: =AVERAGE(C6:G6) -> 12.8 | I6: =_xlfn.STDEV.P(C6:G6) -> 7.7820306 | L6: Escenario No. 4 | M6: {=TRANSPOSE(H37:H44)} -> 0 | N6: #DIV/0! | O6: #DIV/0! | P6: #DIV/0! | Q6: #DIV/0! | R6: #DIV/0! | S6: #DIV/0! | T6: #DIV/0!
B7: Número de pacientes vivos | C7: 31 | D7: 36 | E7: 40 | F7: 35 | G7: 30 | H7: =AVERAGE(C7:G7) -> 34.4 | I7: =_xlfn.STDEV.P(C7:G7) -> 3.611094 | L7: Escenario No. 5 | M7: {=TRANSPOSE(H48:H55)} -> 100 | N7: 86.6 | O7: 13.4 | P7: 34.4 | Q7: 5.6 | R7: 52.2 | S7: 7.8 | T7: 35.6
B8: Número de pacientes muertos | C8: 9 | D8: 4 | E8: 0 | F8: 5 | G8: 10 | H8: =AVERAGE(C8:G8) -> 5.6 | I8: =_xlfn.STDEV.P(C8:G8) -> 3.611094 | L8: Escenario No. 6 | M8: {=TRANSPOSE(H59:H66)} -> 100 | N8: 78.666667 | O8: 21.333333 | P8: 0 | Q8: 0 | R8: 0 | S8: 0 | T8: 320.8
B9: Número de sanos vivos | C9: 51 | D9: 51 | E9: 58 | F9: 58 | G9: 46 | H9: =AVERAGE(C9:G9) -> 52.8 | I9: =_xlfn.STDEV.P(C9:G9) -> 4.621688 | L9: Escenario No. 7 | M9: {=TRANSPOSE(H70:H77)} -> 120 | N9: 89 | O9: 31 | P9: 41.666667 | Q9: 18.333333 | R9: 47.333333 | S9: 12.666667 | T9: 293.6
B10: Número de sanos muertos | C10: 9 | D10: 9 | E10: 2 | F10: 2 | G10: 14 | H10: =AVERAGE(C10:G10) -> 7.2 | I10: =_xlfn.STDEV.P(C10:G10) -> 4.621688 | L10: Escenario No. 8 | M10: {=TRANSPOSE(H98:H105)} -> 113 | N10: 101.33333 | O10: 11.666667 | P10: 50.666667 | Q10: 7.6666667 | R10: 50.666667 | S10: 4 | T10: 366.66667
B11: Tiempo promedio de evacuación | C11: 59 | D11: 60 | E11: 49 | F11: 65 | G11: 47 | H11: =AVERAGE(C11:G11) -> 56 | I11: =_xlfn.STDEV.P(C11:G11) -> 6.8702256 | L11: Escenario No. 9 | M11: {=TRANSPOSE(H109:H116)} -> 100 | N11: 99 | O11: 1 | P11: 49.333333 | Q11: 0.66666667 | R11: 49.666667 | S11: 0.33333333 | T11: 346.66667
A13: Table 4 | B13: Escenario No. 2: THE IMPACTOF THE LARGE NUMBER OF AGENTS TO EVACUATE
B14: Resultados | C14: S1 | D14: S2 | E14: S3 | F14: S4 | G14: S5 | H14: Promedio | I14: Desv. Estandar
B15: Individuos en el ambiente | C15: =C16+C17 -> 290 | D15: =D16+D17 -> 290 | E15: =E16+E17 -> 290 | F15: =F16+F17 -> 290 | G15: =G16+G17 -> 290 | H15: =AVERAGE(C15:G15) -> 290 | I15: =_xlfn.STDEV.P(C15:G15) -> 0
B16: Número de individuos vivos | C16: 180 | D16: 193 | E16: 216 | F16: 211 | G16: 188 | H16: =AVERAGE(C16:G16) -> 197.6 | I16: =_xlfn.STDEV.P(C16:G16) -> 13.720058
B17: Número de individuos muertos | C17: 110 | D17: 97 | E17: 74 | F17: 79 | G17: 102 | H17: =AVERAGE(C17:G17) -> 92.4 | I17: =_xlfn.STDEV.P(C17:G17) -> 13.720058
B18: Número de pacientes vivos | C18: 64 | D18: 71 | E18: 77 | F18: 79 | G18: 66 | H18: =AVERAGE(C18:G18) -> 71.4 | I18: =_xlfn.STDEV.P(C18:G18) -> 5.8855756
B19: Número de pacientes muertos | C19: 44 | D19: 37 | E19: 31 | F19: 29 | G19: 42 | H19: =AVERAGE(C19:G19) -> 36.6 | I19: =_xlfn.STDEV.P(C19:G19) -> 5.8855756
B20: Número de sanos vivos | C20: 116 | D20: 122 | E20: 139 | F20: 132 | G20: 122 | H20: =AVERAGE(C20:G20) -> 126.2 | I20: =_xlfn.STDEV.P(C20:G20) -> 8.2073138
B21: Número de sanos muertos | C21: 66 | D21: 60 | E21: 43 | F21: 50 | G21: 60 | H21: =AVERAGE(C21:G21) -> 55.8 | I21: =_xlfn.STDEV.P(C21:G21) -> 8.2073138
B22: Tiempo promedio de evacuación | C22: 65 | D22: 75 | E22: 79 | F22: 69 | G22: 70 | H22: =AVERAGE(C22:G22) -> 71.6 | I22: =_xlfn.STDEV.P(C22:G22) -> 4.8826222
A24: Table 5 | B24: Escenario No. 3: THE IMPACTOF FIRE POSITIONING
B25: Resultados | C25: S1 | D25: S2 | E25: S3 | F25: S4 | G25: S5 | H25: Promedio | I25: Desv. Estandar
B26: Individuos en el ambiente | C26: =C27+C28 -> 110 | D26: =D27+D28 -> 110 | E26: =E27+E28 -> 110 | F26: =F27+F28 -> 110 | G26: =G27+G28 -> 110 | H26: =AVERAGE(C26:G26) -> 110 | I26: =_xlfn.STDEV.P(C26:G26) -> 0
B27: Número de individuos vivos | C27: 65 | D27: 73 | E27: 82 | F27: 65 | G27: 76 | H27: =AVERAGE(C27:G27) -> 72.2 | I27: =_xlfn.STDEV.P(C27:G27) -> 6.5543878
B28: Número de individuos muertos | C28: 45 | D28: 37 | E28: 28 | F28: 45 | G28: 34 | H28: =AVERAGE(C28:G28) -> 37.8 | I28: =_xlfn.STDEV.P(C28:G28) -> 6.5543878
B29: Número de pacientes vivos | C29: 32 | D29: 38 | E29: 45 | F29: 31 | G29: 43 | H29: =AVERAGE(C29:G29) -> 37.8 | I29: =_xlfn.STDEV.P(C29:G29) -> 5.6356011
B30: Número de pacientes muertos | C30: 28 | D30: 22 | E30: 15 | F30: 29 | G30: 17 | H30: =AVERAGE(C30:G30) -> 22.2 | I30: =_xlfn.STDEV.P(C30:G30) -> 5.6356011
B31: Número de sanos vivos | C31: 33 | D31: 35 | E31: 37 | F31: 34 | G31: 33 | H31: =AVERAGE(C31:G31) -> 34.4 | I31: =_xlfn.STDEV.P(C31:G31) -> 1.496663
B32: Número de sanos muertos | C32: 17 | D32: 15 | E32: 13 | F32: 16 | G32: 17 | H32: =AVERAGE(C32:G32) -> 15.6 | I32: =_xlfn.STDEV.P(C32:G32) -> 1.496663
B33: Tiempo promedio de evacuación | C33: 45 | D33: 47 | E33: 47 | F33: 48 | G33: 39 | H33: =AVERAGE(C33:G33) -> 45.2 | I33: =_xlfn.STDEV.P(C33:G33) -> 3.2496154
A35: Table 6 | B35: Escenario No. 4: ADDING TWO ADDITIONAL TRANSVERSE DOORS TO THE EXISTING ONES
B36: Resultados | C36: S1 | D36: S2 | E36: S3 | F36: S4 | G36: S5 | H36: Promedio | I36: Desv. Estandar
B37: Individuos en el ambiente | C37: =C38+C39 -> 0 | D37: =D38+D39 -> 0 | E37: =E38+E39 -> 0 | F37: =F38+F39 -> 0 | G37: =G38+G39 -> 0 | H37: =AVERAGE(C37:G37) -> 0 | I37: =_xlfn.STDEV.P(C37:G37) -> 0
B38: Número de individuos vivos | H38: =AVERAGE(C38:G38) -> #DIV/0! | I38: =_xlfn.STDEV.P(C38:G38) -> #DIV/0!
B39: Número de individuos muertos | H39: =AVERAGE(C39:G39) -> #DIV/0! | I39: =_xlfn.STDEV.P(C39:G39) -> #DIV/0!
B40: Número de pacientes vivos | H40: =AVERAGE(C40:G40) -> #DIV/0! | I40: =_xlfn.STDEV.P(C40:G40) -> #DIV/0!
B41: Número de pacientes muertos | H41: =AVERAGE(C41:G41) -> #DIV/0! | I41: =_xlfn.STDEV.P(C41:G41) -> #DIV/0!
B42: Número de sanos vivos | H42: =AVERAGE(C42:G42) -> #DIV/0! | I42: =_xlfn.STDEV.P(C42:G42) -> #DIV/0!
B43: Número de sanos muertos | H43: =AVERAGE(C43:G43) -> #DIV/0! | I43: =_xlfn.STDEV.P(C43:G43) -> #DIV/0!
...
